Workbook

Sheet プログラム開発・導入作業依頼書
U2: プログラム開発／導入作業依頼書
B3: 苦情／不良障害： | G3: □ | H3: 受付番号： | K3: 2 | L3: 0 | M3: － | N3: 2 | O3: 3 | P3: 0 | Q3: 5 | R3: 0 | S3: 0 | T3: 1 | U3: 6 | AG3: PGへの開発依頼： | AH3: 有 | AI3: PG開発受付印 | AM3: PG担当開始 | AQ3: 単体テスト実施 | AU3: PG担当終了 | AY3: PG開発完了承認印
B4: 原価管理ID | H4: 起案番号 | N4: [名称] | P4: 開_即出荷対応(EPC) | AB4: 希望納期
B5: A123KBD010 | H5: E3123KBD01 | AB5: 回答納期
B6: 課題No. | H6: タスク(システムフロー)No. | N6: [名称] | P6: 未指示紐付数取得処理(API)
H7: R20WT80
B8: プロジェクトリーダ | F8: 設計担当 | J8: 見積 | L8: モジュール数 | O8: ステップ数 | R8: 帳票数 | U8: 画面数 | X8: File数 | Z8: 設計見積 | AC8: 開発見積 | AF8: 実績 | AH8: ﾓｼﾞｭｰﾙ数 | AK8: ステップ数 | AO8: 帳票数 | AR8: 画面数 | AU8: File数 | AW8: Q/A・不具合数 | BA8: PG工数
J9: 新作 | AF9: 新作 | AK9: 実：
AK10: コ：
J11: 修正 | AF11: 修正
AB12: (h) | AE12: (h) | BC12: (h)
B13: 依頼区分１ | I13: ① | J13: 初回 | L13: 2 | M13: 出荷前 | O13: 3 | P13: 出荷後 | AC13: PG から 設計 への連絡事項 又は、PGクレーム原因･対策 | AT13: 導入部門への添付資料
B14: 依頼区分２ | I14: ① | J14: 新規 | L14: 修正（ | N14: 2 | O14: 要変 | Q14: 3 | R14: 設不 | T14: 4 | U14: P不） | W14: 5 | X14: 廃止 | Z14: 6 | AA14: 調査 | AT14: アウトプット資料一覧表
B15: 稼働環境区分 | I15: 1 | J15: HOST | L15: ② | M15: Server | O15: 3 | P15: 両方 | R15: 9 | S15: その他（ | AB15: ） | AT15: インプット資料一覧表
B16: オンライン，バッチ，集約区分 | I16: ① | J16: Online | L16: 2 | M16: バッチ | O16: 3 | P16: 集約 | R16: 9 | S16: その他（ | AB16: ) | AT16: レコード仕様書
B17: 開発言語 | I17: 1 | J17: PL/I | L17: 2 | M17: COBOL | O17: ③ | P17: Java | R17: 4 | S17: Asteria | U17: 5 | V17: RC | W17: 6 | X17: ABAP | Z17: 7 | AA17: .NET | AT17: ファイル仕様書
I18: 8 | J18: Create!PDF | O18: 9 | P18: その他( | AB18: ) | AT18: データベース仕様書
B19: 動作（A/R）Mode(DB2のみ) | I19: ① | J19: 31/31 | L19: 2 | M19: 31/24 | O19: 3 | P19: 24/24 | S19: ウォークスルー | W19: 1 | X19: 要 | Y19: ② | Z19: 否 | AT19: システムフローチャート
B20: 西暦年(DB2のみ) | I20: ① | J20: 4桁 | L20: 2 | M20: 2桁 | S20: 単体テスト | W20: ① | X20: 要 | Y20: 2 | Z20: 否(目視) | AT20: タスク仕様書(IMSのみ)
B21: 設計 から PG への依頼事項(参考するシステムフロー、汎用モジュール等) 又は、PGクレーム現象 | AT21: コンピュータ処理概要仕様書
B22: 変更履歴の№XXを参照願いします。_x000D_ 案件名：E3123KBD01 KAP2/KWIN2改善_x000D_ 原価管理ID：A123KBD010 開_即出荷対応(EPC) | AT22: 本番LIB登録依頼書
AT23: JCLリスト
AT24: ワークファイル仕様書
AT25: プログラム/タスクフローチャート
AT26: JCL MASTER SCAN リスト
B28: =IF(OR(N14="②",Q14="③",T14="④",W14="⑤")," 注）JCLの変更が必要になるモジュール変更，廃止の場合にはJCLMASTER SCANを実行すること","")
B29: 設計から導入部門への依頼事項 初回ランに関する事項(手順登録) スケジュールに関する事項(前後グルーピング) その他(BOQ伝送に関する事項 等) | AT29: PG から 導入部門 への連絡事項
AI31: 新規＆ホスト＆バッチの場合は以下をマーク
AI32: オンラインスタートに関係 | AP32: 有 | AQ32: □ | AR32: 無 | AS32: □
AI33: 緊急コール必要 | AP33: 有 | AQ33: □ | AR33: 無 | AS33: □
AI34: 翌朝まで放置 | AP34: 可 | AQ34: □ | AR34: 否 | AS34: □
B35: 導入依頼印 | G35: 本番LIB登録期間 | R35: 導入部門受付印 | W35: 導入担当印 | AB35: スケジュールコード | AH35: LPRM 本番登録№ | AT35: 電子帳票登録(FIB)
AU36: 有 | AV36: □ | AW36: 無 | AX36: □
G37: 導入完了希望日 | AH37: オペマニ有無 | AN37: JCL有無 | AT37: ASPOOL登録 | AY37: MAP登録
G38: 本番実施日 | AH38: 新 | AI38: □ | AJ38: 有 | AK38: □ | AL38: 無 | AM38: □ | AN38: 新 | AO38: □ | AP38: 有 | AQ38: □ | AR38: 無 | AS38: □ | AU38: 有 | AV38: □ | AW38: 無 | AX38: □ | AZ38: 有 | BA38: □ | BB38: 無 | BC38: □
E40: 記入不要

Sheet 変更履歴
X1: 変更履歴
A3: Webサービス名 | I3: =IF(表紙!$I3="","",表紙!I3) -> R20WT80_未指示紐付数取得処理(API) | AR3: 文書番号
A4: サブシステム名 | I4: =IF(表紙!$I4="","",表紙!I4) -> 工程管理 | AR4: 作成日 | AU4: =表紙!$AT$4 -> 45063 | AY4: 作成者 | BB4: KIS
A5: システム名 | I5: =IF(表紙!$I5="","",表紙!I5) -> KAPS2 | AR5: 更新日 | AU5: 45198 | AY5: 更新者 | BB5: 山藤
A6: プロジェクト名 | I6: =IF(表紙!$I6="","",表紙!I6) -> R20WKapsJsonSV
A8: No | C8: 版/稿 | F8: 更新日 | J8: 更新者 | O8: シート名 | V8: 変更内容・理由
A9: 受付番号：2023050016 原価管理ID／名：A123KBD010／未指示紐付け部品即出荷対応_クロスドック2(EPC対応)
A10: 1 | F10: 45040 | J10: KIS | V10: 新規
A11: 2 | F11: 45198 | J11: 山藤 | O11: 表紙 | V11: 受注台帳を追加
O12: WebサービスIF仕様 | V12: レスポンスデータの項目削除 国内EO紐付数、ＳＯ紐付数、ＲＯ紐付数、輸出ＥＯ紐付数、ＷＯ紐付数、国内ＰＯ紐付数、輸出ＰＯ紐付数、ＩＯ紐付数、 ＣＯ紐付数、ＴＯ紐付数、ＤＤＳ紐付数、輸出ＭＯ紐付数、緊急積送紐付数、通常積送紐付数 レスポンスデータの項目追加 紐付情報リスト（受付№、受付行番号、オーダー種別、紐付数、受付日、受付時刻、新旧フラグ）
O13: (移)140 | V13: 各種紐付数の移送を廃止し、受注紐付情報の明細を移送するように変更
O14: (移)160 | V14: 各種紐付数の移送を廃止し、積送紐付情報の明細を移送するように変更
O15: (編)1A0 | V15: レスポンスデータの変更に合わせて、ログ出力内容を変更
O16: SQL仕様書 | V16: 下記SQLを変更（紐付数の合計を取得するSQLを、紐付情報の明細を取得するSQLに変更） select.001 select.002

Sheet 表紙
X1: Webサービス詳細設計書（表紙）
A3: Webサービス名 | I3: R20WT80_未指示紐付数取得処理(API) | AA3: 【 設計書の構成 】 | AQ3: 文書番号
A4: サブシステム名 | I4: 工程管理 | AA4: □ | AB4: WebサービスIF仕様 | AI4: ■ | AJ4: 構成図 | AQ4: 作成日 | AT4: 45063 | AX4: 作成者 | BA4: KIS
A5: システム名 | I5: KAPS2 | AA5: ■ | AB5: SQL仕様書 | AI5: ■ | AJ5: 編集要領書 | AQ5: 更新日 | AT5: 45198 | AX5: 更新者 | BA5: 山藤
A6: プロジェクト名 | I6: R20WKapsJsonSV | AA6: □ | AI6: ■ | AJ6: 項目移送定義書
A8: 【 処理全体図 】 | AA8: 【 処理概要 】
AB10: 未指示紐付数のデータを取得するWEBサービス。
AA15: 【 処理構成 - セクション】
AA16: Job名 | AJ16: No. | AN16: 処理
AA17: 未指示紐付数取得処理 | AJ17: 110 | AM17: 入力パラメータ取得
AJ18: 120 | AM18: 入力パラメータチェック
AJ19: 125 | AM19: 出力パラメータ初期化
AJ20: 126 | AM20: 変数の初期化
AJ21: 130 | AM21: 受注紐付数検索
AJ22: 140 | AM22: 受注紐付数出力
AJ23: 150 | AM23: 積送紐付数検索
AJ24: 160 | AM24: 積送紐付数出力
AJ25: 170 | AM25: 緊急サイン検索
AJ26: 180 | AM26: 緊急サイン出力
AJ27: 190 | AM27: データリスト追加
AJ28: 1A0 | AM28: 出力パラメータ設定
AA38: No. | AC38: テーブル/ファイル名 | AM38: No. | AO38: クラス/エンティティ
AA39: 1 | AC39: 未指示紐付台帳
AA40: 2 | AC40: 未指示台帳
AA41: 3 | AC41: 積送要求台帳
AA42: 4 | AC42: 発注台帳
AA43: 5 | AC43: 受注台帳 | AH43: 2023/9/29 追加

Sheet WebサービスIF仕様
X1: WebサービスIF仕様
A3: Webサービス名 | I3: =IF(表紙!$I3="","",表紙!I3) -> R20WT80_未指示紐付数取得処理(API) | AA3: セクション | AH3: WebサービスIF仕様 | AR3: 文書番号
A4: サブシステム名 | I4: =IF(表紙!$I4="","",表紙!I4) -> 工程管理 | AR4: 作成日 | AU4: =表紙!$AT$4 -> 45063 | AY4: 作成者 | BB4: KIS
A5: システム名 | I5: =IF(表紙!$I5="","",表紙!I5) -> KAPS2 | AR5: 更新日 | AU5: 45198 | AY5: 更新者 | BB5: 山藤
A6: プロジェクト名 | I6: =IF(表紙!$I6="","",表紙!I6) -> R20WKapsJsonSV
A8: 【 Webサービス基本仕様 】
B10: 項目名 | R10: 内容 | AU10: 補足
B11: リクエストパス（URL) 検証環境 | R11: http://133.253.116.3:8091/kaps2/R20WKapsJsonSV/webapi/r20wt80.do
B12: リクエストパス（URL) 本番環境 | R12: http://133.253.62.137:8091/kaps2/R20WKapsJsonSV/webapi/r20wt80.do
B13: 文字コード | R13: UTF-8
B14: 認証処理のパターン | R14: 認証なし
B15: リクエストメソッド | R15: POST
B16: リクエストデータ形式 | R16: JSON
B17: レスポンスデータ形式 | R17: JSON
A19: 【 リクエストデータ 】
B21: 項目名 | L21: 項目ID | R21: 内容 | AU21: 補足
B22: 検索条件リスト | L22: criteriaList | R22: 複数指定 | AU22: 上限10
C23: 注番 | L23: chuban
A27: 【 リクエスト形式 】
B29: 形式(JSON形式の場合に記述する)
C31: {
D32: "criteriaList":[
E33: {
F34: "chuBan":"15325889"
E35: },
E36: {
F37: "chuBan":"23012495"
E38: }
D39: ]
C40: }
A43: 【 レスポンスデータ 】
B45: 項目名 | L45: 項目ID | R45: 内容 | AU45: 補足
B46: 処理結果コード | L46: resultCode | R46: 0:正常終了、4：警告、8:アプリケーションエラー、-1:システムエラー
B47: 処理結果詳細 | L47: resultDetail
C48: 検索結果リスト | L48: dataList | R48: 検索結果の件数分繰り返す
D49: 明細ステータス | L49: meisaiStatus | R49: "00"正常終了、エラー時には、エラーコードを設定する
D50: 明細ステータスメッセージ | L50: meisaiStatusMsg
D51: 国内EO紐付数 | L51: eodom | BD51: 2023/9/29 削除
D52: ＳＯ紐付数 | L52: soexp | BD52: 2023/9/29 削除
D53: ＲＯ紐付数 | L53: rodom | BD53: 2023/9/29 削除
...

Sheet 構成図
X1: 処理構成図
A3: Webサービス名 | I3: =IF(表紙!$I3="","",表紙!$I$3) -> R20WT80_未指示紐付数取得処理(API) | AA3: セクション | AH3: 処理構成図 | AR3: 文書番号
A4: サブシステム名 | I4: =IF(表紙!$I4="","",表紙!$I$4) -> 工程管理 | AA4: メソッド名 | AE4: process | AR4: 作成日 | AU4: =表紙!$AT$4 -> 45063 | AY4: 作成者 | BB4: KIS
A5: システム名 | I5: =IF(表紙!$I5="","",表紙!$I$5) -> KAPS2 | AA5: クラス名 | AE5: R20WT80WebapiAction | AR5: 更新日 | AY5: 更新者
A6: プロジェクト名 | I6: =IF(表紙!$I6="","",表紙!$I$6) -> R20WKapsJsonSV
D9: （１）入力パラメータ取得（Sec110 getMyBean）
D11: （２）入力パラメータチェック（Sec120 checkInput）
AE13: 戻り値 ＝ 2：異常終了
C14: No | AW14: Yes
D15: （３）出力パラメータ初期化（Sec125） | AJ15: 出力パラメータにエラー情報をセットし異常終了
AK16: (*)エラーコード →(oﾊﾟ)エラーコード
C17: (iﾊﾟ)検索条件リストのレコードがなくなるまで繰り返す | AK17: (*)エラーメッセージ→(oﾊﾟ)エラーメッセージ
F19: （３－１）変数の初期化（Sec126）
F21: （４）受注紐付数検索（Sec130 getOrderRecvLinkCount）
Z23: 戻り値 ＝ 1：継続終了
E24: No | AI24: Yes
F25: （５）受注紐付数出力（Sec140 setOrderRecvLinkCount）
F27: （６）積送紐付数検索（Sen150 getShipmentLinkCount）
W29: 戻り値 ＝ 1：継続終了
E30: No | AF30: Yes
F31: （７）積送紐付数出力（Sec160 setShipmentLinkCount）
F33: （８）緊急サインの取得（Sen170 getUrgentSign）
T35: 戻り値 ＝ 1：継続終了
E36: No | AC36: Yes
F37: （９）緊急サイン出力（Sec180 setUrgentSign）
F39: （１０）処理結果セット（Sec190 setShoriKekka） | AA39: （１０）処理結果セット
AA40: （Sec190 setShoriKekka）
D41: （１１）出力パラメータ設定（Sec1A0 setMyBean）
G42: ※検索条件と処理結果をログ出力する
D43: ※正常終了の時は戻り値：success、異常終了の時は戻り値：error

Sheet (補足)Bean関連
A1: ※初期構築時のBeanクラス構造理解のための資料なので、メンテ不要
A2: 構造が著しく複雑になったらメンテ検討
B4: Beanクラス定義 | AM4: 設計書 | AU4: ソース利用箇所
B5: 型 | R5: 変数名 | AF5: 初期化 | AM5: 変数名 | AU5: 宣言 | BC5: 初期化/セット箇所
B6: R20WT80OutputBean | AM6: (*)処理結果 | AV6: outputBean | BC6: processメソッドでインスタンス化（Sec125）
BC7: Sec1A0で(oﾊﾟ)処理結果詳細"resultDetail"として格納される
C9: List<R20WT80OutputDataBean> | R9: dataList | X9: 検索結果リスト | AF9: private宣言で生成 | AM9: (*)処理結果リスト | AV9: dataList | BC9: processメソッドfor文内で取得（Sec126） | BR9: outputBean.getDataList();
BC10: Sec190でリストデータ（dataBean）追加
D12: R20WT80OutputDataBean | X12: 処理結果詳細 | AM12: (*)処理結果詳細 | AV12: dataBean | BC12: processメソッドfor文内でインスタンス化（Sec126）
E13: String | R13: meisaiStatus | X13: 明細ステータス | AF13: private宣言でﾌﾞﾗﾝｸ | AW13: meisaiStatus | BC13: Sec190
E14: String | R14: meisaiStatusMsg | X14: 明細ステータスMSG | AF14: private宣言でﾌﾞﾗﾝｸ | AW14: meisaiStatusMsg | BC14: Sec190
E15: String | R15: esign | X15: 緊急サイン | AF15: private宣言でﾌﾞﾗﾝｸ | AW15: esign | BC15: Sec180
E16: String | R16: ekbn | X16: 緊急区分 | AF16: private宣言でﾌﾞﾗﾝｸ | AW16: ekbn | BC16: Sec180
E17: String | R17: comment | X17: コメント | AF17: private宣言でﾌﾞﾗﾝｸ | AW17: comment | BC17: Sec180
E19: List<R20WT80OutputHimoinfBean> | R19: himoinfList | X19: 紐付情報リスト | AF19: private宣言で生成 | AW19: himoinfList | BC19: Sec140/Sec160で取得 | BL19: dataBean.getHimoinfList()
BC20: Sec140/Sec160のfor文内でリストデータ（himoinfBean）追加
F22: R20WT80OutputHimoinfBean | X22: 紐付情報詳細 | AV22: himoinfBean | BC22: Sec140/Sec160のfor文内でインスタンス化
G24: String | R24: ukeno | X24: 受付№ | AF24: private宣言でﾌﾞﾗﾝｸ | AW24: ukeno | BC24: Sec140/Sec160のfor文内
G25: String | R25: ukegyo | X25: 受付行番号 | AF25: private宣言でﾌﾞﾗﾝｸ | AW25: ukegyo | BC25: Sec140/Sec160のfor文内
G26: String | R26: odertyp | X26: オーダー種別 | AF26: private宣言でﾌﾞﾗﾝｸ | AW26: odertyp | BC26: Sec140/Sec160のfor文内
G27: BigDecimal | R27: htksu | X27: 紐付数 | AF27: private宣言で0 | AW27: htksu | BC27: Sec140/Sec160のfor文内
G28: String | R28: recdate | X28: 受付日 | AF28: private宣言でﾌﾞﾗﾝｸ | AW28: recdate | BC28: Sec140/Sec160のfor文内
G29: String | R29: rectime | X29: 受付時刻 | AF29: private宣言でﾌﾞﾗﾝｸ | AW29: rectime | BC29: Sec140/Sec160のfor文内
G30: String | R30: onflg | X30: 新旧フラグ | AF30: private宣言でﾌﾞﾗﾝｸ | AW30: onflg | BC30: Sec140/Sec160のfor文内
C33: (iﾊﾟ)検索条件リストの件数分、(*)処理結果詳細を作成し(*)処理結果リストに追加していく
C34: (*)処理結果は、Sec1A0で(oﾊﾟ)処理結果詳細にセットする

Sheet (編)110
X1: 編集要領書
A3: Webサービス名 | I3: =IF(表紙!$I3="","",表紙!I3) -> R20WT80_未指示紐付数取得処理(API) | AA3: セクション | AE3: 110 | AH3: 入力パラメータ取得 | AR3: 文書番号
A4: サブシステム名 | I4: =IF(表紙!$I4="","",表紙!I4) -> 工程管理 | AA4: メソッド名 | AE4: getMyBean | AR4: 作成日 | AU4: =表紙!$AT$4 -> 45063 | AY4: 作成者 | BB4: KIS
A5: システム名 | I5: =IF(表紙!$I5="","",表紙!I5) -> KAPS2 | AA5: クラス名 | AE5: R20WT80WebapiAction | AR5: 更新日 | AY5: 更新者
A6: プロジェクト名 | I6: =IF(表紙!$I6="","",表紙!I6) -> R20WKapsJsonSV
B8: 入力（項目名） | Y8: 編 集 方 法 | AY8: 出力（項目名）
I10: 1. 変数の初期化
K11: ブランク | AX11: (*)エラーコード
K12: ブランク | AX12: (*)エラーメッセージ
K13: '00' | AX13: (*)明細ステータス
K14: ブランク | AX14: (*)明細ステータスメッセージ
I16: 2. 入力パラメータを取得
A17: (iﾊﾟ)すべて | J17: Jason文字列からBean変換(JsonUtil.parse）を使用して、入力パラメータをすべて取得する
I19: 3. 入力パラメータを出力パラメータにセット
A20: (iﾊﾟ)すべて | AX20: (oﾊﾟ)リクエストデータ

Sheet (編)120
X1: 編集要領書
A3: Webサービス名 | I3: =IF(表紙!$I3="","",表紙!I3) -> R20WT80_未指示紐付数取得処理(API) | AA3: セクション | AE3: 120 | AH3: 入力パラメータチェック | AR3: 文書番号
A4: サブシステム名 | I4: =IF(表紙!$I4="","",表紙!I4) -> 工程管理 | AA4: メソッド名 | AE4: checkInput | AR4: 作成日 | AU4: =表紙!$AT$4 -> 45063 | AY4: 作成者 | BB4: KIS
A5: システム名 | I5: =IF(表紙!$I5="","",表紙!I5) -> KAPS2 | AA5: クラス名 | AE5: R20WT80WebapiAction | AR5: 更新日 | AY5: 更新者
A6: プロジェクト名 | I6: =IF(表紙!$I6="","",表紙!I6) -> R20WKapsJsonSV
B8: 入力（項目名） | Y8: 編 集 方 法 | AY8: 出力（項目名）
I10: 1. 入力パラメータチェック
A11: (iﾊﾟ)検索条件リスト | J11: 1) | K11: 検索条件リストの件数が上限件数（10）を超える場合、エラーとし、処理を終了する。
L12: EWT80001 | AX12: (*)エラーコード
L13: 入力パラメータ最大値（MAX_COUNT_CRITERIA） | AX13: (*)エラーメッセージ[0]
L14: 2(異常終了) | AX14: 戻り値
K15: 以後、処理を行わず本セクションを抜ける
A17: (iﾊﾟ)検索条件リスト | J17: 2) | K17: 検索条件リストの件数が0の場合、エラーとし、処理を終了する。
L18: EWT80002 | AX18: (*)エラーコード
L19: null | AX19: (*)エラーメッセージ
L20: 2(異常終了) | AX20: 戻り値
K21: 以後、処理を行わず本セクションを抜ける
I23: 2. 正常終了の戻り値を返す
J24: 0(正常終了) | AX24: 戻り値

Sheet (編)125
X1: 編集要領書
A3: Webサービス名 | I3: =IF(表紙!$I3="","",表紙!I3) -> R20WT80_未指示紐付数取得処理(API) | AA3: セクション | AE3: 125 | AH3: 出力パラメータ初期化 | AR3: 文書番号
A4: サブシステム名 | I4: =IF(表紙!$I4="","",表紙!I4) -> 工程管理 | AA4: メソッド名 | AR4: 作成日 | AU4: =表紙!$AT$4 -> 45063 | AY4: 作成者 | BB4: KIS
A5: システム名 | I5: =IF(表紙!$I5="","",表紙!I5) -> KAPS2 | AA5: クラス名 | AE5: R20WT80WebapiAction | AR5: 更新日 | AY5: 更新者
A6: プロジェクト名 | I6: =IF(表紙!$I6="","",表紙!I6) -> R20WKapsJsonSV
B8: 入力（項目名） | Y8: 編 集 方 法 | AY8: 出力（項目名）
I10: 1. 出力パラメータの初期化
K11: インスタンス生成 | U11: 型：R20WT80OutputBean | AX11: (*)処理結果

Sheet (編)126
X1: 編集要領書
A3: Webサービス名 | I3: =IF(表紙!$I3="","",表紙!I3) -> R20WT80_未指示紐付数取得処理(API) | AA3: セクション | AE3: 126 | AH3: 変数の初期化 | AR3: 文書番号
A4: サブシステム名 | I4: =IF(表紙!$I4="","",表紙!I4) -> 工程管理 | AA4: メソッド名 | AR4: 作成日 | AU4: 45383 | AY4: 作成者 | BB4: 玄野
A5: システム名 | I5: =IF(表紙!$I5="","",表紙!I5) -> KAPS2 | AA5: クラス名 | AE5: R20WT80WebapiAction | AR5: 更新日 | AY5: 更新者
A6: プロジェクト名 | I6: =IF(表紙!$I6="","",表紙!I6) -> R20WKapsJsonSV
B8: 入力（項目名） | Y8: 編 集 方 法 | AY8: 出力（項目名）
I10: 1. 変数の初期化
K11: (*)処理結果．処理結果リスト | U11: 型：List<R20WT80OutputDataBean> | AX11: (*)処理結果リスト
K12: インスタンス生成 | U12: 型：R20WT80OutputDataBean | AX12: (*)処理結果詳細
V13: ※(*)処理結果リストの1データ。レスポンスデータの処理結果詳細．検索結果リストと同じ構成

Sheet (編)130
X1: 編集要領書
A3: Webサービス名 | I3: =IF(表紙!$I3="","",表紙!I3) -> R20WT80_未指示紐付数取得処理(API) | AA3: セクション | AE3: 130 | AH3: 受注紐付数検索 | AR3: 文書番号
A4: サブシステム名 | I4: =IF(表紙!$I4="","",表紙!I4) -> 工程管理 | AA4: メソッド名 | AE4: getOrderRecvLinkCount | AR4: 作成日 | AU4: =表紙!$AT$4 -> 45063 | AY4: 作成者 | BB4: KIS
A5: システム名 | I5: =IF(表紙!$I5="","",表紙!I5) -> KAPS2 | AA5: クラス名 | AE5: R20WT80WebapiAction | AR5: 更新日 | AY5: 更新者
A6: プロジェクト名 | I6: =IF(表紙!$I6="","",表紙!I6) -> R20WKapsJsonSV
B8: 入力（項目名） | Y8: 編 集 方 法 | AY8: 出力（項目名）
A10: (iﾊﾟ)検索条件リスト | I10: 1. (iﾊﾟ)検索条件リスト．注番＝ブランク の場合
K11: EWT80002 | AX11: (*)明細ステータス
K12: null | AX12: (*)明細ステータスメッセージ
K13: 1(継続終了) | AX13: 戻り値
J14: 以後、処理を行わず本セクションを抜ける
I16: 2. 受注紐付数検索
K17: PARAM | N17: ユーザークラス．会社コード | AX17: (*)受注紐付数検索リスト
K18: PARAM | N18: (iパ)検索条件リスト．注番 | AX18: List<Map<String,Object>>
K19: 【SQL_ID】 | O19: select.001 | AX19: orderRecvList
I21: 3. 正常終了の戻り値を返す
J22: 0(正常終了) | AX22: 戻り値

Sheet (編)140
X1: 編集要領書
A3: Webサービス名 | I3: =IF(表紙!$I3="","",表紙!I3) -> R20WT80_未指示紐付数取得処理(API) | AA3: セクション | AE3: 140 | AH3: 受注紐付数出力 | AR3: 文書番号
A4: サブシステム名 | I4: =IF(表紙!$I4="","",表紙!I4) -> 工程管理 | AA4: メソッド名 | AE4: setOrderRecvLinkCount | AR4: 作成日 | AU4: =表紙!$AT$4 -> 45063 | AY4: 作成者 | BB4: KIS
A5: システム名 | I5: =IF(表紙!$I5="","",表紙!I5) -> KAPS2 | AA5: クラス名 | AE5: R20WT80WebapiAction | AR5: 更新日 | AY5: 更新者
A6: プロジェクト名 | I6: =IF(表紙!$I6="","",表紙!I6) -> R20WKapsJsonSV
B8: 入力（項目名） | Y8: 編 集 方 法 | AY8: 出力（項目名）
A10: (*)受注紐付数検索リスト | I10: 1. (*)受注紐付数検索リストの件数分、(*)処理結果詳細の紐付情報の編集を行う
J12: 1) | K12: 編集方法は、(移)140を参照 | AX12: (*)処理結果詳細

Sheet (移)140
X1: 項目移送定義書
A3: Webサービス名 | I3: =IF(表紙!$I3="","",表紙!$I$3) -> R20WT80_未指示紐付数取得処理(API) | AA3: セクション | AE3: 140 | AH3: 受注紐付数出力 | AR3: 文書番号
A4: サブシステム名 | I4: =IF(表紙!$I4="","",表紙!$I$4) -> 工程管理 | AA4: メソッド名 | AE4: setOrderRecvLinkCount | AR4: 作成日 | AU4: =表紙!$AT$4 -> 45063 | AY4: 作成者 | BB4: KIS
A5: システム名 | I5: =IF(表紙!$I5="","",表紙!$I$5) -> KAPS2 | AA5: クラス名 | AE5: R20WT80WebapiAction | AR5: 更新日 | AU5: 45198 | AY5: 更新者 | BB5: 山藤
A6: プロジェクト名 | I6: =IF(表紙!$I6="","",表紙!$I$6) -> R20WKapsJsonSV
B8: 編集先 | G8: 項目 | T8: 編集元 | Z8: 項目 | AM8: 編集方法
A10: (*)処理結果詳細 | G10: 処理結果リスト | BF10: 2023/9/29 削除
H11: 国内EO紐付数 | T11: 受注紐付数検索結果 | Z11: 紐付数 | AM11: 受注形態区分='01'の紐付数を加算する | BF11: 2023/9/29 削除
H12: ＳＯ紐付数 | T12: 受注紐付数検索結果 | Z12: 紐付数 | AM12: 受注形態区分='02'の紐付数を加算する | BF12: 2023/9/29 削除
H13: ＲＯ紐付数 | T13: 受注紐付数検索結果 | Z13: 紐付数 | AM13: 受注形態区分='03'の紐付数を加算する | BF13: 2023/9/29 削除
H14: 輸出ＥＯ紐付数 | T14: 受注紐付数検索結果 | Z14: 紐付数 | AM14: 受注形態区分='04'の紐付数を加算する | BF14: 2023/9/29 削除
H15: ＷＯ紐付数 | T15: 受注紐付数検索結果 | Z15: 紐付数 | AM15: 受注形態区分='05'の紐付数を加算する | BF15: 2023/9/29 削除
H16: 国内ＰＯ紐付数 | T16: 受注紐付数検索結果 | Z16: 紐付数 | AM16: 受注形態区分='06' and 国内外区分='1'の紐付数を加算する | BF16: 2023/9/29 削除
H17: 輸出ＰＯ紐付数 | T17: 受注紐付数検索結果 | Z17: 紐付数 | AM17: 受注形態区分='06' and 国内外区分='2'の紐付数を加算する | BF17: 2023/9/29 削除
H18: ＩＯ紐付数 | T18: 受注紐付数検索結果 | Z18: 紐付数 | AM18: 受注形態区分='07'の紐付数を加算する | BF18: 2023/9/29 削除
H19: ＣＯ紐付数 | T19: 受注紐付数検索結果 | Z19: 紐付数 | AM19: 受注形態区分='08'の紐付数を加算する | BF19: 2023/9/29 削除
H20: ＴＯ紐付数 | T20: 受注紐付数検索結果 | Z20: 紐付数 | AM20: 受注形態区分='09'の紐付数を加算する | BF20: 2023/9/29 削除
H21: ＤＤＳ紐付数 | T21: 受注紐付数検索結果 | Z21: 紐付数 | AM21: 受注形態区分='10'の紐付数を加算する | BF21: 2023/9/29 削除
H22: 輸出ＭＯ紐付数 | T22: 受注紐付数検索結果 | Z22: 紐付数 | AM22: 受注形態区分='11'の紐付数を加算する | BF22: 2023/9/29 削除
A24: (*)処理結果詳細 | G24: 紐付情報リスト | T24: 受注紐付数検索リスト | BF24: 2023/9/29 追加
H25: 受付№ | T25: 未指示台帳 | Z25: 受付№ | BF25: 2023/9/29 追加
H26: 受付行番号 | T26: 未指示台帳 | Z26: 受付行番号 | BF26: 2023/9/29 追加
H27: オーダー種別 | T27: 未指示台帳 | Z27: 受注形態区分 | BF27: 2023/9/29 追加
H28: 紐付数 | T28: 未指示紐付台帳 | Z28: 紐付数 | BF28: 2023/9/29 追加
H29: 受付日 | T29: 受注台帳 | Z29: 受注日 | AM29: YYYY/MM/DD | BF29: 2023/9/29 追加
H30: 受付時刻 | T30: 受注台帳 | Z30: 受注時刻 | AM30: HH:MM:SS | BF30: 2023/9/29 追加
H31: 新旧フラグ | T31: 未指示台帳 | Z31: 国内海外区分 | AM31: (1)国内海外区分＝'1'の場合 ①受注形態区分＝'01'(EO)の場合、'0'(旧) ②上記以外の場合 受注台帳．得意先コード or '999999'で検索した キューイングシステム振分マスター．得意先コードが ブランクでない場合、'1'(新) ブランクの場合、'0'(旧) (2)上記(1)以外の場合、'0'(旧) | BF31: 2023/9/29 追加
T32: 未指示台帳 | Z32: 受注形態区分 | BF32: 2023/9/29 追加
T33: キューイングシステム振分マスター | Z33: 得意先コード | BF33: 2023/9/29 追加

Sheet (編)150
X1: 編集要領書
A3: Webサービス名 | I3: =IF(表紙!$I3="","",表紙!I3) -> R20WT80_未指示紐付数取得処理(API) | AA3: セクション | AE3: 150 | AH3: 積送紐付数検索 | AR3: 文書番号
A4: サブシステム名 | I4: =IF(表紙!$I4="","",表紙!I4) -> 工程管理 | AA4: メソッド名 | AE4: getShipmentLinkCount | AR4: 作成日 | AU4: =表紙!$AT$4 -> 45063 | AY4: 作成者 | BB4: KIS
A5: システム名 | I5: =IF(表紙!$I5="","",表紙!I5) -> KAPS2 | AA5: クラス名 | AE5: R20WT80WebapiAction | AR5: 更新日 | AY5: 更新者
A6: プロジェクト名 | I6: =IF(表紙!$I6="","",表紙!I6) -> R20WKapsJsonSV
B8: 入力（項目名） | Y8: 編 集 方 法 | AY8: 出力（項目名）
A10: (iﾊﾟ)検索条件リスト | I10: 1. 積数紐付数検索
K11: PARAM | M11: ユーザークラス．会社コード | AX11: (*)積送紐付数検索リスト
K12: PARAM | M12: (iﾊﾟ)検索条件リスト．注番
K13: 【SQL_ID】 | O13: select.002
J15: 1) | K15: (*)受注紐付数検索リストの件数＝0 かつ (*)積送紐付数検索リストの件数 = 0 の場合
L16: EWT80003 | AX16: (*)明細ステータス
L17: null | AX17: (*)明細ステータスメッセージ
L18: 1(継続終了) | AX18: 戻り値
K19: 以後、処理を行わず本セクションを抜ける
I21: 2. 正常終了の戻り値を返す
J22: 0(正常終了) | AX22: 戻り値

Sheet (編)160
X1: 編集要領書
A3: Webサービス名 | I3: =IF(表紙!$I3="","",表紙!I3) -> R20WT80_未指示紐付数取得処理(API) | AA3: セクション | AE3: 160 | AH3: 積送紐付数出力 | AR3: 文書番号
A4: サブシステム名 | I4: =IF(表紙!$I4="","",表紙!I4) -> 工程管理 | AA4: メソッド名 | AE4: setShipmentLinkCount | AR4: 作成日 | AU4: =表紙!$AT$4 -> 45063 | AY4: 作成者 | BB4: KIS
A5: システム名 | I5: =IF(表紙!$I5="","",表紙!I5) -> KAPS2 | AA5: クラス名 | AE5: R20WT80WebapiAction | AR5: 更新日 | AY5: 更新者
A6: プロジェクト名 | I6: =IF(表紙!$I6="","",表紙!I6) -> R20WKapsJsonSV
B8: 入力（項目名） | Y8: 編 集 方 法 | AY8: 出力（項目名）
A10: (*)積数紐付数検索リスト | I10: 1. (*)積数紐付数検索リストの件数分、(*)処理結果詳細の紐付情報の編集を行う
J12: 1) | K12: 編集方法は、(移)160を参照 | AX12: (*)処理結果詳細

Sheet (移)160
X1: 項目移送定義書
A3: Webサービス名 | I3: =IF(表紙!$I3="","",表紙!$I$3) -> R20WT80_未指示紐付数取得処理(API) | AA3: セクション | AE3: 160 | AH3: 積数紐付数の取得 | AR3: 文書番号
A4: サブシステム名 | I4: =IF(表紙!$I4="","",表紙!$I$4) -> 工程管理 | AA4: メソッド名 | AE4: setShipmentLinkCount | AR4: 作成日 | AU4: =表紙!$AT$4 -> 45063 | AY4: 作成者 | BB4: KIS
A5: システム名 | I5: =IF(表紙!$I5="","",表紙!$I$5) -> KAPS2 | AA5: クラス名 | AE5: R20WT80WebapiAction | AR5: 更新日 | AU5: 45198 | AY5: 更新者 | BB5: 山藤
A6: プロジェクト名 | I6: =IF(表紙!$I6="","",表紙!$I$6) -> R20WKapsJsonSV
B8: 編集先 | G8: 項目 | T8: 編集元 | Z8: 項目 | AM8: 編集方法
A10: (*)処理結果詳細 | G10: 処理結果リスト | BF10: 2023/9/29 削除
H11: 緊急積送紐付数 | T11: 積送紐付数検索結果 | Z11: 紐付数 | AM11: 特記事項コード='9'の紐付数を加算する | BF11: 2023/9/29 削除
H12: 通常積送紐付数 | T12: 積送紐付数検索結果 | Z12: 紐付数 | AM12: 特記事項コード<>'9'の紐付数を加算する | BF12: 2023/9/29 削除
A14: (*)処理結果詳細 | G14: 紐付情報リスト | T14: 積送紐付数検索リスト | BF14: 2023/9/29 追加
H15: 受付№ | T15: 未指示台帳 | Z15: 受付№ | BF15: 2023/9/29 追加
H16: 受付行番号 | T16: 未指示台帳 | Z16: 受付行番号 | BF16: 2023/9/29 追加
H17: オーダー種別 | T17: 積送要求台帳 | Z17: 特記事項コード | AM17: (1)特記事項コード＝'9'の場合 ①完備子部品積送サイン＝'1'の場合、'22' ②上記以外の場合、'21' (2)上記(1)以外の場合 ①完備子部品積送サイン＝'1'の場合、'24' ②上記以外の場合、'23' | BF17: 2023/9/29 追加
T18: 未指示台帳 | Z18: 完備子部品積送サイン | BF18: 2023/9/29 追加
H19: 紐付数 | T19: 未指示紐付台帳 | Z19: 紐付数 | BF19: 2023/9/29 追加
H20: 受付日 | T20: 積送要求台帳 | Z20: 積送要求日 | AM20: YYYY/MM/DD | BF20: 2023/9/29 追加
H21: 受付時刻 | T21: 積送要求台帳 | Z21: 積送要求時刻 | AM21: HH:MM:SS | BF21: 2023/9/29 追加
H22: 新旧フラグ | T22: 未指示台帳 | Z22: 国内海外区分 | AM22: (1)国内海外区分＝'1'の場合 積送要求台帳．得意先コード or '999999'で検索した キューイングシステム振分マスター．得意先コードが ブランクでない場合、'1'(新) ブランクの場合、'0'(旧) (2)上記(1)以外の場合、'0'(旧) | BF22: 2023/9/29 追加
T23: キューイングシステム振分マスター | Z23: 得意先コード | BF23: 2023/9/29 追加

Sheet (編)170
X1: 編集要領書
A3: Webサービス名 | I3: =IF(表紙!$I3="","",表紙!I3) -> R20WT80_未指示紐付数取得処理(API) | AA3: セクション | AE3: 170 | AH3: 緊急サイン検索 | AR3: 文書番号
A4: サブシステム名 | I4: =IF(表紙!$I4="","",表紙!I4) -> 工程管理 | AA4: メソッド名 | AE4: getUrgentSign | AR4: 作成日 | AU4: =表紙!$AT$4 -> 45063 | AY4: 作成者 | BB4: KIS
A5: システム名 | I5: =IF(表紙!$I5="","",表紙!I5) -> KAPS2 | AA5: クラス名 | AE5: R20WT80WebapiAction | AR5: 更新日 | AY5: 更新者
A6: プロジェクト名 | I6: =IF(表紙!$I6="","",表紙!I6) -> R20WKapsJsonSV
B8: 入力（項目名） | Y8: 編 集 方 法 | AY8: 出力（項目名）
A10: (iﾊﾟ)検索条件リスト | I10: 1. 緊急サイン検索 | AX10: (*)緊急サイン検索リスト
K11: PARAM | M11: ユーザークラス．会社コード
K12: PARAM | M12: (iﾊﾟ)検索条件リスト．注番
K13: 【SQL_ID】 | O13: select.003
J15: 1) | K15: (*)緊急サイン検索リストの件数 = 0 の場合
L16: EWT80004 | AX16: (*)明細ステータス
L17: null | AX17: (*)明細ステータスメッセージ
L18: 1(継続終了) | AX18: 戻り値
K19: 以後、処理を行わず本セクションを抜ける
I21: 2. 正常終了の戻り値を返す
J22: 0(正常終了) | AX22: 戻り値

Sheet (編)180
X1: 編集要領書
A3: Webサービス名 | I3: =IF(表紙!$I3="","",表紙!I3) -> R20WT80_未指示紐付数取得処理(API) | AA3: セクション | AE3: 180 | AH3: 緊急サイン出力 | AR3: 文書番号
A4: サブシステム名 | I4: =IF(表紙!$I4="","",表紙!I4) -> 工程管理 | AA4: メソッド名 | AE4: setUrgentSign | AR4: 作成日 | AU4: =表紙!$AT$4 -> 45063 | AY4: 作成者 | BB4: KIS
A5: システム名 | I5: =IF(表紙!$I5="","",表紙!I5) -> KAPS2 | AA5: クラス名 | AE5: R20WT80WebapiAction | AR5: 更新日 | AY5: 更新者
A6: プロジェクト名 | I6: =IF(表紙!$I6="","",表紙!I6) -> R20WKapsJsonSV
B8: 入力（項目名） | Y8: 編 集 方 法 | AY8: 出力（項目名）
A10: (*)緊急サイン検索リスト | I10: 1. (*)緊急サイン検索リストの件数分、緊急サインの編集を行う
J12: 1) | K12: 編集方法は、(移)180を参照 | AX12: (*)処理結果詳細

Sheet (移)180
X1: 項目移送定義書
A3: Webサービス名 | I3: =IF(表紙!$I3="","",表紙!$I$3) -> R20WT80_未指示紐付数取得処理(API) | AA3: セクション | AE3: 160 | AH3: 積数紐付数の取得 | AR3: 文書番号
A4: サブシステム名 | I4: =IF(表紙!$I4="","",表紙!$I$4) -> 工程管理 | AA4: メソッド名 | AE4: setShipmentLinkCount | AR4: 作成日 | AU4: =表紙!$AT$4 -> 45063 | AY4: 作成者 | BB4: KIS
A5: システム名 | I5: =IF(表紙!$I5="","",表紙!$I$5) -> KAPS2 | AA5: クラス名 | AE5: R20WT80WebapiAction | AR5: 更新日 | AY5: 更新者
A6: プロジェクト名 | I6: =IF(表紙!$I6="","",表紙!$I$6) -> R20WKapsJsonSV
B8: 編集先 | G8: 項目 | T8: 編集元 | Z8: 項目 | AM8: 編集方法
A10: (*)処理結果詳細
G11: 緊急サイン | T11: 緊急サイン検索リスト | Z11: 緊急サイン
G12: 緊急区分 | Z12: ブランク
G13: コメント | Z13: ブランク

Sheet (編)190
X1: 編集要領書
A3: Webサービス名 | I3: =IF(表紙!$I3="","",表紙!I3) -> R20WT80_未指示紐付数取得処理(API) | AA3: セクション | AE3: 190 | AH3: 処理結果セット | AR3: 文書番号
A4: サブシステム名 | I4: =IF(表紙!$I4="","",表紙!I4) -> 工程管理 | AA4: メソッド名 | AE4: setShoriKekka | AR4: 作成日 | AU4: =表紙!$AT$4 -> 45063 | AY4: 作成者 | BB4: KIS
A5: システム名 | I5: =IF(表紙!$I5="","",表紙!I5) -> KAPS2 | AA5: クラス名 | AE5: R20WT80WebapiAction | AR5: 更新日 | AY5: 更新者
A6: プロジェクト名 | I6: =IF(表紙!$I6="","",表紙!I6) -> R20WKapsJsonSV
B8: 入力（項目名） | Y8: 編 集 方 法 | AY8: 出力（項目名）
I10: 1. (*)明細ステータス＝'00'の場合
J11: 1) | K11: (*)処理結果詳細に明細ステータスをセット | AX11: (*)処理結果詳細
L12: '00' | AY12: 明細ステータス
L13: ブランク | AY13: 明細ステータスメッセージ
J15: 2) | K15: (*)処理結果詳細を(*)処理結果リストに追加 | AX15: (*)処理結果リスト
I17: 2. 上記1.以外の場合
J18: 1) | K18: (*)処理結果詳細に明細ステータスをセット | AX18: (*)処理結果詳細
L19: (*)明細ステータス | AY19: 明細ステータス
L20: (*)明細ステータスメッセージから編集したメッセージ | AD20: ※メッセージの内容は【WebサービスIF仕様】シートを参照 | AY20: 明細ステータスMSG
J22: 2) | K22: (*)処理結果詳細を(*)処理結果リストに追加 | AX22: (*)処理結果リスト
J24: 3) | K24: (*)明細ステータスを初期化
L25: '00' | AX25: (*)明細ステータス
L26: ブランク | AX26: (*)明細ステータスメッセージ
J28: 4) | K28: (*)エラーコード≠ブランクの場合
K29: ① | L29: 出力パラメータのエラー情報をセット
M30: (*)エラーコード | AX30: (oﾊﾟ)エラーコード
M31: (*)エラーメッセージから編集したメッセージ | AX31: (oﾊﾟ)エラーメッセージ

Sheet (編)1A0
X1: 編集要領書
A3: Webサービス名 | I3: =IF(表紙!$I3="","",表紙!I3) -> R20WT80_未指示紐付数取得処理(API) | AA3: セクション | AE3: 1A0 | AH3: 出力パラメータ設定 | AR3: 文書番号
A4: サブシステム名 | I4: =IF(表紙!$I4="","",表紙!I4) -> 工程管理 | AA4: メソッド名 | AE4: setMyBean | AR4: 作成日 | AU4: =表紙!$AT$4 -> 45063 | AY4: 作成者 | BB4: KIS
A5: システム名 | I5: =IF(表紙!$I5="","",表紙!I5) -> KAPS2 | AA5: クラス名 | AE5: R20WT80WebapiAction | AR5: 更新日 | AU5: 45198 | AY5: 更新者 | BB5: 山藤
A6: プロジェクト名 | I6: =IF(表紙!$I6="","",表紙!I6) -> R20WKapsJsonSV
B8: 入力（項目名） | Y8: 編 集 方 法 | AY8: 出力（項目名）
I10: 1. 入力パラメータの検索条件をログ出力する。
A11: (iﾊﾟ)検索条件リスト | J11: 各行１桁目から(iﾊﾟ)検索条件リストのみを出力する
J12: 検索条件
J13: 注番=XXXXXXXX
J14: 注番=XXXXXXXX
J15: 注番=XXXXXXXX
J16: 注番=XXXXXXXX
J17: 注番=XXXXXXXX
J18: 注番=XXXXXXXX
J19: 注番=XXXXXXXX
J20: 注番=XXXXXXXX
J21: 注番=XXXXXXXX
J22: 注番=XXXXXXXX
I24: 2. 処理結果をログ出力する
A25: (*)処理結果リスト | J25: 各行の1桁目から処理結果を出力する
J26: 処理結果
J27: ｽﾃｰﾀｽ=00,ﾒｯｾｰｼﾞ=,EOｺｸﾅｲ=0,SO=4,RO=10,EOﾕｼｭﾂ=6,WO=0,POｺｸﾅｲ=0,POﾕｼｭﾂ=0,IO=0,CO=0,TO=0,DDS=0,MOﾕｼｭﾂ=0,ｷﾝｷｭｳｾｷｿｳ=5,ﾂｳｼﾞｮｳｾｷｿｳ=0,ｷﾝｷｭｳｻｲﾝ=1,ｷﾝｷｭｳｸﾌﾞﾝ=,ｺﾒﾝﾄ= | BF27: 2023/9/29 削除
J28: ｽﾃｰﾀｽ=00,ﾒｯｾｰｼﾞ=,EOｺｸﾅｲ=0,SO=4,RO=10,EOﾕｼｭﾂ=6,WO=0,POｺｸﾅｲ=0,POﾕｼｭﾂ=0,IO=0,CO=0,TO=0,DDS=0,MOﾕｼｭﾂ=0,ｷﾝｷｭｳｾｷｿｳ=5,ﾂｳｼﾞｮｳｾｷｿｳ=0,ｷﾝｷｭｳｻｲﾝ=1,ｷﾝｷｭｳｸﾌﾞﾝ=,ｺﾒﾝﾄ= | BF28: 2023/9/29 削除
J29: ｽﾃｰﾀｽ=00,ﾒｯｾｰｼﾞ=,EOｺｸﾅｲ=0,SO=4,RO=10,EOﾕｼｭﾂ=6,WO=0,POｺｸﾅｲ=0,POﾕｼｭﾂ=0,IO=0,CO=0,TO=0,DDS=0,MOﾕｼｭﾂ=0,ｷﾝｷｭｳｾｷｿｳ=5,ﾂｳｼﾞｮｳｾｷｿｳ=0,ｷﾝｷｭｳｻｲﾝ=1,ｷﾝｷｭｳｸﾌﾞﾝ=,ｺﾒﾝﾄ= | BF29: 2023/9/29 削除
J30: ｽﾃｰﾀｽ=00,ﾒｯｾｰｼﾞ=,EOｺｸﾅｲ=0,SO=4,RO=10,EOﾕｼｭﾂ=6,WO=0,POｺｸﾅｲ=0,POﾕｼｭﾂ=0,IO=0,CO=0,TO=0,DDS=0,MOﾕｼｭﾂ=0,ｷﾝｷｭｳｾｷｿｳ=5,ﾂｳｼﾞｮｳｾｷｿｳ=0,ｷﾝｷｭｳｻｲﾝ=1,ｷﾝｷｭｳｸﾌﾞﾝ=,ｺﾒﾝﾄ= | BF30: 2023/9/29 削除
J31: ｽﾃｰﾀｽ=00,ﾒｯｾｰｼﾞ=,EOｺｸﾅｲ=0,SO=4,RO=10,EOﾕｼｭﾂ=6,WO=0,POｺｸﾅｲ=0,POﾕｼｭﾂ=0,IO=0,CO=0,TO=0,DDS=0,MOﾕｼｭﾂ=0,ｷﾝｷｭｳｾｷｿｳ=5,ﾂｳｼﾞｮｳｾｷｿｳ=0,ｷﾝｷｭｳｻｲﾝ=1,ｷﾝｷｭｳｸﾌﾞﾝ=,ｺﾒﾝﾄ= | BF31: 2023/9/29 削除
J32: ｽﾃｰﾀｽ=00,ﾒｯｾｰｼﾞ=,EOｺｸﾅｲ=0,SO=4,RO=10,EOﾕｼｭﾂ=6,WO=0,POｺｸﾅｲ=0,POﾕｼｭﾂ=0,IO=0,CO=0,TO=0,DDS=0,MOﾕｼｭﾂ=0,ｷﾝｷｭｳｾｷｿｳ=5,ﾂｳｼﾞｮｳｾｷｿｳ=0,ｷﾝｷｭｳｻｲﾝ=1,ｷﾝｷｭｳｸﾌﾞﾝ=,ｺﾒﾝﾄ= | BF32: 2023/9/29 削除
J33: ｽﾃｰﾀｽ=00,ﾒｯｾｰｼﾞ=,EOｺｸﾅｲ=0,SO=4,RO=10,EOﾕｼｭﾂ=6,WO=0,POｺｸﾅｲ=0,POﾕｼｭﾂ=0,IO=0,CO=0,TO=0,DDS=0,MOﾕｼｭﾂ=0,ｷﾝｷｭｳｾｷｿｳ=5,ﾂｳｼﾞｮｳｾｷｿｳ=0,ｷﾝｷｭｳｻｲﾝ=1,ｷﾝｷｭｳｸﾌﾞﾝ=,ｺﾒﾝﾄ= | BF33: 2023/9/29 削除
J34: ｽﾃｰﾀｽ=00,ﾒｯｾｰｼﾞ=,EOｺｸﾅｲ=0,SO=4,RO=10,EOﾕｼｭﾂ=6,WO=0,POｺｸﾅｲ=0,POﾕｼｭﾂ=0,IO=0,CO=0,TO=0,DDS=0,MOﾕｼｭﾂ=0,ｷﾝｷｭｳｾｷｿｳ=5,ﾂｳｼﾞｮｳｾｷｿｳ=0,ｷﾝｷｭｳｻｲﾝ=1,ｷﾝｷｭｳｸﾌﾞﾝ=,ｺﾒﾝﾄ= | BF34: 2023/9/29 削除
J35: ｽﾃｰﾀｽ=00,ﾒｯｾｰｼﾞ=,EOｺｸﾅｲ=0,SO=4,RO=10,EOﾕｼｭﾂ=6,WO=0,POｺｸﾅｲ=0,POﾕｼｭﾂ=0,IO=0,CO=0,TO=0,DDS=0,MOﾕｼｭﾂ=0,ｷﾝｷｭｳｾｷｿｳ=5,ﾂｳｼﾞｮｳｾｷｿｳ=0,ｷﾝｷｭｳｻｲﾝ=1,ｷﾝｷｭｳｸﾌﾞﾝ=,ｺﾒﾝﾄ= | BF35: 2023/9/29 削除
J36: ｽﾃｰﾀｽ=00,ﾒｯｾｰｼﾞ=,EOｺｸﾅｲ=0,SO=4,RO=10,EOﾕｼｭﾂ=6,WO=0,POｺｸﾅｲ=0,POﾕｼｭﾂ=0,IO=0,CO=0,TO=0,DDS=0,MOﾕｼｭﾂ=0,ｷﾝｷｭｳｾｷｿｳ=5,ﾂｳｼﾞｮｳｾｷｿｳ=0,ｷﾝｷｭｳｻｲﾝ=1,ｷﾝｷｭｳｸﾌﾞﾝ=,ｺﾒﾝﾄ= | BF36: 2023/9/29 削除
J37: ｽﾃｰﾀｽ=00,ﾒｯｾｰｼﾞ=,ｷﾝｷｭｳｻｲﾝ=1,ｷﾝｷｭｳｸﾌﾞﾝ=,ｺﾒﾝﾄ= | BF37: 2023/9/29 追加
J38: 受付№=,受付行番号=,オーダー種別=,紐付数=,受付日=,受付時刻=,新旧フラグ= | BF38: 2023/9/29 追加
... J45: … (検索結果リストの件数分出力する) | BF45: 2023/9/29 追加
J46: ※=の後に、値を出力する
I48: 3. 処理結果を出力パラメータにセットする
A49: (*)処理結果 | AX49: (oﾊﾟ)処理結果詳細
B50: (*)処理結果リスト | AY50: 検索結果リスト
C51: 明細ステータス | AZ51: 明細ステータス
...

Sheet SQL仕様書
X1: ＳＱＬ仕様書
A3: Webサービス名 | I3: =IF(表紙!$I3="","",表紙!$I$3) -> R20WT80_未指示紐付数取得処理(API) | AH3: ＳＱＬ仕様書 | AR3: 文書番号
A4: サブシステム名 | I4: =IF(表紙!$I4="","",表紙!$I$4) -> 工程管理 | AR4: 作成日 | AU4: =表紙!$AT$4 -> 45063 | AY4: 作成者 | BB4: KIS
A5: システム名 | I5: =IF(表紙!$I5="","",表紙!$I$5) -> KAPS2 | AR5: 更新日 | AU5: 45198 | AY5: 更新者 | BB5: 山藤
A6: プロジェクト名 | I6: =IF(表紙!$I6="","",表紙!$I$6) -> R20WKapsJsonSV
B8: ＳＱＬ ＩＤ | I8: ＳＱＬ定義書
A9: select.001 | I9: SELECT | AU9: 2023/9/29 削除 | BF9: SELECT
J10: B.国内外区分 | BG10: B.CNATABR
J11: ,B.受注形態区分 | BG11: ,B.CJUCKTI
J12: ,sum(A.紐付数) | BG12: ,SUM(A.SHTK) AS SHTK
I13: FROM | BF13: FROM
J14: 未指示紐付台帳 AS A | BG14: DMSZHTK AS A
J15: INNER JOIN 未指示台帳 AS B | BG15: INNER JOIN DMSZ AS B
J16: ON( | BF16: ON (
K17: B.会社コード = A.会社コード | BF17: B.BPRFKAI = A.BPRFKAI
K18: AND B.削除区分 = A.削除区分 | BF18: AND B.CSKJ = A.CSKJ
K19: AND B.受付№ = A.受付№ | BF19: AND B.BUKE = A.BUKE
K20: AND B.受付行番号 = A.受付行番号 | BF20: AND B.BUKEGYO = A.BUKEGYO
J21: ) | BF21: )
I22: WHERE | BF22: WHERE
J23: A.会社コード = (User)会社コード | BF23: A.BPRFKAI = ?
J24: AND A.削除区分 = ' ' | BF24: AND A.CSKJ = ' '
J25: AND A.注番 = (iパ)注番 | BF25: AND A.BCHB = ?
J26: AND B.受注積送区分 = '1' | BF26: AND B.CJUCSSO = '1'
I27: GROUP BY | BF27: GROUP BY
J28: B.国内外区分 | BF28: B.CNATABR
J29: ,B.受注形態区分 | BF29: ,B.CJUCKTI
I32: SELECT | AU32: 2023/9/29 追加 | BF32: SELECT
I33: 受付№ | BF33: BUKE
I34: ,受付行番号 | BF34: ,BUKEGYO
I35: ,受注形態区分 | BF35: ,CJUCKTI
I36: ,紐付数 | BF36: ,SHTK
I37: ,受注日 | BF37: ,DJUCDAT
I38: ,受注時刻 | BF38: ,DJUCTIM
I39: ,国内海外区分 | BF39: ,CNATABR
I40: ,得意先コード | BF40: ,BTKU
I41: FROM ( | BF41: FROM (
I42: SELECT | BF42: SELECT
I43: B.受付№ | BF43: B.BUKE
I44: ,B.受付行番号 | BF44: ,B.BUKEGYO
...
